<?xml version="1.0" ?>
<!-- =================================================================================== -->
<!-- |    This document was autogenerated by xacro from /home/sam/fast_ws/src/dyno/dyno_description/robots/forklift.xacro | -->
<!-- |    EDITING THIS FILE BY HAND IS NOT RECOMMENDED                                 | -->
<!-- =================================================================================== -->
<robot name="dyno_forklift" xmlns:xacro="http://ros.org/wiki/xacro">
  <material name="black">
    <color rgba="0.0 0.0 0.0 1.0"/>
  </material>
  <material name="dark">
    <color rgba="0.3 0.3 0.3 1.0"/>
  </material>
  <material name="light_black">
    <color rgba="0.4 0.4 0.4 1.0"/>
  </material>
  <material name="blue">
    <color rgba="0.0 0.0 0.8 1.0"/>
  </material>
  <material name="light_blue">
    <color rgba="0.3 0.3 0.8 1.0"/>
  </material>
  <material name="green">
    <color rgba="0.0 0.8 0.0 1.0"/>
  </material>
  <material name="grey">
    <color rgba="0.5 0.5 0.5 1.0"/>
  </material>
  <material name="orange">
    <color rgba="1.0 0.423529411765 0.0392156862745 1.0"/>
  </material>
  <material name="brown">
    <color rgba="0.870588235294 0.811764705882 0.764705882353 1.0"/>
  </material>
  <material name="red">
    <color rgba="0.8 0.0 0.0 1.0"/>
  </material>
  <material name="white">
    <color rgba="1.0 1.0 1.0 1.0"/>
  </material>
  <gazebo>
    <plugin filename="libgazebo_ros_control.so" name="gazebo_ros_control">
      <robotSimType>gazebo_ros_control/DefaultRobotHWSim</robotSimType>
    </plugin>
    <plugin filename="libgazebo_ros_p3d.so" name="ground_truth">
      <frameName>map</frameName>
      <bodyName>base_footprint</bodyName>
      <topicName>base_pose_ground_truth</topicName>
      <updateRate>30.0</updateRate>
    </plugin>
  </gazebo>
  <gazebo reference="drive_wheel_link">
    <material>Gazebo/Black</material>
    <kp>1000000.0</kp>
    <kd>100.0</kd>
    <mu1>1</mu1>
    <mu2>1</mu2>
    <fdir1>1 0 0</fdir1>
    <minDepth>0.003</minDepth>
    <maxVel>1.0</maxVel>
  </gazebo>
  <gazebo reference="steer_link">
    <material>Gazebo/SkyBlue</material>
  </gazebo>
  <gazebo reference="imu_link">
    <sensor name="imu" type="imu">
      <imu>
        <angular_velocity>
          <x>
            <noise type="gaussian">
              <mean>0.0</mean>
              <stddev>2e-4</stddev>
              <bias_mean>0.0000075</bias_mean>
              <bias_stddev>0.0000008</bias_stddev>
            </noise>
          </x>
          <y>
            <noise type="gaussian">
              <mean>0.0</mean>
              <stddev>2e-4</stddev>
              <bias_mean>0.0000075</bias_mean>
              <bias_stddev>0.0000008</bias_stddev>
            </noise>
          </y>
          <z>
            <noise type="gaussian">
              <mean>0.0</mean>
              <stddev>2e-4</stddev>
              <bias_mean>0.0000075</bias_mean>
              <bias_stddev>0.0000008</bias_stddev>
            </noise>
          </z>
        </angular_velocity>
        <linear_acceleration>
          <x>
            <noise type="gaussian">
              <mean>0.0</mean>
              <stddev>1.7e-2</stddev>
              <bias_mean>0.1</bias_mean>
              <bias_stddev>0.001</bias_stddev>
            </noise>
          </x>
          <y>
            <noise type="gaussian">
              <mean>0.0</mean>
              <stddev>1.7e-2</stddev>
              <bias_mean>0.1</bias_mean>
              <bias_stddev>0.001</bias_stddev>
            </noise>
          </y>
          <z>
            <noise type="gaussian">
              <mean>0.0</mean>
              <stddev>1.7e-2</stddev>
              <bias_mean>0.1</bias_mean>
              <bias_stddev>0.001</bias_stddev>
            </noise>
          </z>
        </linear_acceleration>
      </imu>
    </sensor>
    <material>Gazebo/Grey</material>
  </gazebo>
  <gazebo>
    <plugin filename="libgazebo_ros_imu.so" name="imu_plugin">
      <visualize>true</visualize>
      <alwaysOn>true</alwaysOn>
      <bodyName>imu_link</bodyName>
      <frameName>imu_link</frameName>
      <topicName>imu</topicName>
      <serviceName>imu_service</serviceName>
      <gaussianNoise>0.0</gaussianNoise>
      <updateRate>200</updateRate>
    </plugin>
  </gazebo>
  <link name="base_link">
    <visual>
      <origin rpy="0 0 0" xyz="0 0 0"/>
      <geometry>
        <mesh filename="package://dyno_description/meshes/bases/forklift_base.stl" scale="0.01 0.01 0.01"/>
      </geometry>
      <material name="dark"/>
    </visual>
    <collision>
      <origin rpy="0 0 0" xyz="0.2 0 0.14"/>
      <geometry>
        <box size="0.15 0.2 0.3"/>
      </geometry>
      <material name="orange"/>
    </collision>
    <!-- Set high weight and low intertia for gazebot simulation -->
    <inertial>
      <origin rpy="0 0 0" xyz="0.13 0 0"/>
      <mass value="10.0"/>
      <inertia ixx="0.000604166666667" ixy="0" ixz="0" iyy="0.000833333333333" iyz="0" izz="0.00127083333333"/>
    </inertial>
  </link>
  <!-- Base footprint -->
  <link name="base_footprint"/>
  <joint name="base_footprint_joint" type="fixed">
    <origin rpy="0 0 0" xyz="0 0 0.025"/>
    <parent link="base_footprint"/>
    <child link="base_link"/>
  </joint>
  <!-- Fork -->
  <joint name="fork_joint" type="prismatic">
    <origin rpy="0 0 0" xyz="0.106 0 0"/>
    <parent link="base_link"/>
    <child link="fork_link"/>
    <axis xyz="0 0 1"/>
    <limit effort="1000.0" lower="0" upper="1.0" velocity="0.05"/>
  </joint>
  <link name="fork_link">
    <visual>
      <origin rpy="0 0 3.14159265359" xyz="0 0 0"/>
      <geometry>
        <mesh filename="package://dyno_description/meshes/bases/forklift_fork.stl" scale="0.01 0.01 0.01"/>
      </geometry>
      <material name="black"/>
    </visual>
    <collision>
      <origin rpy="0 0 0" xyz="-0.15 0 -0.004"/>
      <geometry>
        <box size="0.24 0.1 0.008"/>
      </geometry>
      <material name="orange"/>
    </collision>
    <inertial>
      <origin rpy="0 0 0" xyz="-0.16 0 0"/>
      <mass value="0.02"/>
      <inertia ixx="1.67733333333e-06" ixy="0" ixz="0" iyy="8.82733333333e-06" iyz="0" izz="1.04833333333e-05"/>
    </inertial>
  </link>
  <transmission name="fork_joint_trans">
    <type>transmission_interface/SimpleTransmission</type>
    <joint name="fork_joint">
      <hardwareInterface>hardware_interface/PositionJointInterface</hardwareInterface>
    </joint>
    <actuator name="fork_joint_motor">
      <mechanicalReduction>10</mechanicalReduction>
      <hardwareInterface>hardware_interface/PositionJointInterface</hardwareInterface>
    </actuator>
  </transmission>
  <link name="support_wheel_right_link">
    <visual>
      <origin rpy="0 0 0" xyz="0 0 0"/>
      <geometry>
        <mesh filename="package://dyno_description/meshes/wheels/forklift_support_wheel.stl" scale="0.01 0.01 0.01"/>
      </geometry>
      <material name="orange"/>
    </visual>
    <collision>
      <origin rpy="0 0 0" xyz="0 0 0"/>
      <geometry>
        <cylinder length="0.011" radius="0.025"/>
      </geometry>
      <material name="orange"/>
    </collision>
    <inertial>
      <origin rpy="0 0 0" xyz="0 0 0"/>
      <mass value="0.1"/>
      <inertia ixx="1.66333333333e-05" ixy="0" ixz="0" iyy="1.66333333333e-05" iyz="0" izz="3.125e-05"/>
    </inertial>
  </link>
  <joint name="support_wheel_right_joint" type="continuous">
    <origin rpy="1.57079632679 0 0" xyz="0 -0.1085 0"/>
    <parent link="base_link"/>
    <child link="support_wheel_right_link"/>
    <axis xyz="0 0 1"/>
    <limit effort="10000" velocity="10000"/>
  </joint>
  <!-- Transmission -->
  <transmission name="support_wheel_right_joint_trans">
    <type>transmission_interface/SimpleTransmission</type>
    <joint name="support_wheel_right_joint">
      <hardwareInterface>hardware_interface/EffortJointInterface</hardwareInterface>
    </joint>
    <actuator name="support_wheel_right_joint_motor">
      <mechanicalReduction>10</mechanicalReduction>
      <hardwareInterface>hardware_interface/EffortJointInterface</hardwareInterface>
    </actuator>
  </transmission>
  <!-- Contact model for the wheel surface -->
  <gazebo reference="support_wheel_right_link">
    <kp>100000.0</kp>
    <kd>100.0</kd>
    <mu1>100.0</mu1>
    <!-- <mu2>1.0</mu2> -->
    <fdir1>1 0 0</fdir1>
    <maxVel>1.0</maxVel>
    <minDepth>0.003</minDepth>
    <implicitSpringDamper>1</implicitSpringDamper>
    <material>Gazebo/Orange</material>
  </gazebo>
  <link name="support_wheel_left_link">
    <visual>
      <origin rpy="0 0 0" xyz="0 0 0"/>
      <geometry>
        <mesh filename="package://dyno_description/meshes/wheels/forklift_support_wheel.stl" scale="0.01 0.01 0.01"/>
      </geometry>
      <material name="orange"/>
    </visual>
    <collision>
      <origin rpy="0 0 0" xyz="0 0 0"/>
      <geometry>
        <cylinder length="0.011" radius="0.025"/>
      </geometry>
      <material name="orange"/>
    </collision>
    <inertial>
      <origin rpy="0 0 0" xyz="0 0 0"/>
      <mass value="0.1"/>
      <inertia ixx="1.66333333333e-05" ixy="0" ixz="0" iyy="1.66333333333e-05" iyz="0" izz="3.125e-05"/>
    </inertial>
  </link>
  <joint name="support_wheel_left_joint" type="continuous">
    <origin rpy="-1.57079632679 0 0" xyz="0 0.1085 0"/>
    <parent link="base_link"/>
    <child link="support_wheel_left_link"/>
    <axis xyz="0 0 1"/>
    <limit effort="10000" velocity="10000"/>
  </joint>
  <!-- Transmission -->
  <transmission name="support_wheel_left_joint_trans">
    <type>transmission_interface/SimpleTransmission</type>
    <joint name="support_wheel_left_joint">
      <hardwareInterface>hardware_interface/EffortJointInterface</hardwareInterface>
    </joint>
    <actuator name="support_wheel_left_joint_motor">
      <mechanicalReduction>10</mechanicalReduction>
      <hardwareInterface>hardware_interface/EffortJointInterface</hardwareInterface>
    </actuator>
  </transmission>
  <!-- Contact model for the wheel surface -->
  <gazebo reference="support_wheel_left_link">
    <kp>100000.0</kp>
    <kd>100.0</kd>
    <mu1>100.0</mu1>
    <!-- <mu2>1.0</mu2> -->
    <fdir1>1 0 0</fdir1>
    <maxVel>1.0</maxVel>
    <minDepth>0.003</minDepth>
    <implicitSpringDamper>1</implicitSpringDamper>
    <material>Gazebo/Orange</material>
  </gazebo>
  <!-- Wheel-->
  <joint name="drive_wheel_joint" type="continuous">
    <origin rpy="-1.57079632679 0 0" xyz="0 0 -0.0453"/>
    <axis xyz="0 0 1"/>
    <limit effort="750.0" velocity="400.0"/>
    <dynamics damping="0.0" friction="0.0"/>
    <parent link="steer_link"/>
    <child link="drive_wheel_link"/>
  </joint>
  <transmission name="drive_wheel_joint_trans">
    <type>transmission_interface/SimpleTransmission</type>
    <joint name="drive_wheel_joint">
      <hardwareInterface>hardware_interface/VelocityJointInterface</hardwareInterface>
    </joint>
    <actuator name="drive_wheel_joint_motor">
      <mechanicalReduction>10</mechanicalReduction>
      <hardwareInterface>hardware_interface/VelocityJointInterface</hardwareInterface>
    </actuator>
  </transmission>
  <link name="drive_wheel_link">
    <inertial>
      <mass value="0.1"/>
      <origin xyz="0 0 0"/>
      <inertia ixx="2.98653333333e-05" ixy="0" ixz="0" iyy="2.98653333333e-05" iyz="0" izz="5.445e-05"/>
    </inertial>
    <visual>
      <geometry>
        <mesh filename="package://dyno_description/meshes/wheels/forklift_drive_wheel.stl" scale="0.01 0.01 0.01"/>
      </geometry>
      <material name="DarkGrey"/>
    </visual>
    <collision>
      <geometry>
        <cylinder length="0.0178" radius="0.033"/>
      </geometry>
    </collision>
  </link>
  <!-- Wheel Steer -->
  <joint name="steer_joint" type="revolute">
    <axis xyz="0 0 1"/>
    <limit effort="1.5" lower="-1.57079632679" upper="1.57079632679" velocity="4.0"/>
    <dynamics damping="0.0" friction="0.0"/>
    <origin rpy="0 0 0" xyz="0.2537 0 0.053"/>
    <parent link="base_link"/>
    <child link="steer_link"/>
  </joint>
  <transmission name="steer_joint_trans">
    <type>transmission_interface/SimpleTransmission</type>
    <joint name="steer_joint">
      <hardwareInterface>hardware_interface/PositionJointInterface</hardwareInterface>
    </joint>
    <actuator name="steer_joint_motor">
      <mechanicalReduction>10</mechanicalReduction>
      <hardwareInterface>hardware_interface/PositionJointInterface</hardwareInterface>
    </actuator>
  </transmission>
  <link name="steer_link">
    <inertial>
      <mass value="0.1"/>
      <origin rpy="0 0 0" xyz="0 0 0"/>
      <inertia ixx="8.89583333333e-05" ixy="0" ixz="0" iyy="8.89583333333e-05" iyz="0" izz="1.125e-05"/>
    </inertial>
    <visual>
      <origin rpy="0 0 0" xyz="0 0 0"/>
      <geometry>
        <mesh filename="package://dyno_description/meshes/bases/forklift_steer.stl" scale="0.01 0.01 0.01"/>
      </geometry>
      <material name="light_blue"/>
    </visual>
    <!--
      <collision>
        <origin xyz="0 0 0.0015" rpy="0 0 0"/>
        <geometry>
          <cylinder length="0.01" radius="0.003"/>
        </geometry>
      </collision>
       -->
  </link>
  <gazebo reference="base_link">
    <material>Gazebo/DarkGrey</material>
  </gazebo>
  <gazebo reference="fork_link">
    <material>Gazebo/Black</material>
  </gazebo>
  <gazebo reference="base_footprint">
    <kp>100000000.0</kp>
    <kd>10.0</kd>
    <mu1>0.1</mu1>
    <mu2>0.1</mu2>
    <fdir1>1 0 0</fdir1>
    <maxVel>10.0</maxVel>
    <minDepth>0.0005</minDepth>
    <laserRetro>0</laserRetro>
  </gazebo>
  <joint name="base_scan_joint" type="fixed">
    <parent link="base_link"/>
    <child link="base_scan_link"/>
    <origin rpy="0 0 0" xyz="0.11 0 0.41"/>
  </joint>
  <link name="base_scan_link">
    <visual>
      <origin rpy="0 0 0" xyz="0 0 0.0"/>
      <geometry>
        <mesh filename="package://dyno_description/meshes/sensors/lds.stl" scale="0.001 0.001 0.001"/>
        <!-- <cylinder length="0.0315" radius="0.055"/> -->
      </geometry>
      <material name="dark"/>
    </visual>
    <collision>
      <origin rpy="0 0 0" xyz="0.015 0 -0.0065"/>
      <geometry>
        <cylinder length="0.0315" radius="0.055"/>
      </geometry>
    </collision>
    <inertial>
      <mass value="0.114"/>
      <origin xyz="0 0 0"/>
      <inertia ixx="0.001" ixy="0.0" ixz="0.0" iyy="0.001" iyz="0.0" izz="0.001"/>
    </inertial>
  </link>
  <gazebo reference="base_scan_link">
    <material>Gazebo/FlatBlack</material>
    <sensor name="lds_lfcd_sensor" type="ray">
      <pose>0 0 0 0 0 0</pose>
      <visualize>false</visualize>
      <ray>
        <scan>
          <horizontal>
            <samples>360</samples>
            <resolution>1</resolution>
            <min_angle>0.0</min_angle>
            <max_angle>6.28319</max_angle>
          </horizontal>
        </scan>
        <range>
          <min>0.120</min>
          <max>3.5</max>
          <resolution>0.015</resolution>
        </range>
        <noise>
          <type>gaussian</type>
          <mean>0.0</mean>
          <stddev>0.01</stddev>
        </noise>
      </ray>
      <plugin filename="libgazebo_ros_laser.so" name="gazebo_ros_lds_lfcd_controller">
        <topicName>scan</topicName>
        <frameName>base_scan_link</frameName>
        <update_rate>1800</update_rate>
      </plugin>
    </sensor>
  </gazebo>
  <!-- Vive Tracker -->
  <!-- <vive_tracker name="vive_tracker" x_offset="0.13" y_offset="0" z_offset="0.391" yaw_offset="0" parent="base_link"/> -->
  <joint name="leap_motion_joint" type="fixed">
    <parent link="fork_link"/>
    <child link="leap_motion_link"/>
    <origin rpy="0 0 3.14159265359" xyz="-0.024 0 0.08"/>
  </joint>
  <link name="leap_motion_link">
    <visual>
      <origin rpy="0 0 0" xyz="0 0 0.0"/>
      <geometry>
        <mesh filename="package://dyno_description/meshes/sensors/leap_motion.dae" scale="0.01 0.01 0.01"/>
      </geometry>
      <!-- <material name="grey"/> -->
    </visual>
    <!--
      <collision>
        <origin xyz="0.015 0 -0.0065" rpy="0 0 0"/>
        <geometry>
          <cylinder length="0.0315" radius="0.055"/>
        </geometry>
      </collision>
      <inertial>
        <mass value="0.114" />
        <origin xyz="0 0 0" />
        <inertia ixx="0.001" ixy="0.0" ixz="0.0"
                 iyy="0.001" iyz="0.0"
                 izz="0.001" />
      </inertial>
     -->
  </link>
  <gazebo reference="leap_motion_link">
    <!-- <material>Gazebo/Grey</material> -->
  </gazebo>
  <link name="imu_link">
    <visual>
      <origin rpy="0 0 0" xyz="0 0 0.0"/>
      <geometry>
        <cylinder length="0.001" radius="0.001"/>
      </geometry>
    </visual>
    <inertial>
      <origin rpy="0 0 0" xyz="0 0 0"/>
      <mass value="0.001"/>
      <inertia ixx="8.66666666667e-09" ixy="0" ixz="0" iyy="8.66666666667e-09" iyz="0" izz="1.66666666667e-08"/>
    </inertial>
  </link>
  <joint name="imu_joint" type="fixed">
    <origin rpy="0 0 0" xyz="0 0 0"/>
    <parent link="base_link"/>
    <child link="imu_link"/>
  </joint>
</robot>

